[2024-07-13T18:41:04.233+0530] {local_task_job_runner.py:120} INFO - ::group::Pre task execution logs
[2024-07-13T18:41:04.400+0530] {taskinstance.py:2076} INFO - Dependencies all met for dep_context=non-requeueable deps ti=<TaskInstance: raw_load_cards.insert_table manual__2024-07-13T13:10:39.894889+00:00 [queued]>
[2024-07-13T18:41:04.417+0530] {taskinstance.py:2076} INFO - Dependencies all met for dep_context=requeueable deps ti=<TaskInstance: raw_load_cards.insert_table manual__2024-07-13T13:10:39.894889+00:00 [queued]>
[2024-07-13T18:41:04.418+0530] {taskinstance.py:2306} INFO - Starting attempt 1 of 1
[2024-07-13T18:41:04.438+0530] {taskinstance.py:2330} INFO - Executing <Task(PythonOperator): insert_table> on 2024-07-13 13:10:39.894889+00:00
[2024-07-13T18:41:04.446+0530] {standard_task_runner.py:63} INFO - Started process 38198 to run task
[2024-07-13T18:41:04.450+0530] {standard_task_runner.py:90} INFO - Running: ['airflow', 'tasks', 'run', 'raw_load_cards', 'insert_table', 'manual__2024-07-13T13:10:39.894889+00:00', '--job-id', '1285', '--raw', '--subdir', 'DAGS_FOLDER/dag_raw_cards.py', '--cfg-path', '/tmp/tmpq1y7_cuw']
[2024-07-13T18:41:04.454+0530] {standard_task_runner.py:91} INFO - Job 1285: Subtask insert_table
[2024-07-13T18:41:04.520+0530] {task_command.py:426} INFO - Running <TaskInstance: raw_load_cards.insert_table manual__2024-07-13T13:10:39.894889+00:00 [running]> on host kali
[2024-07-13T18:41:04.610+0530] {taskinstance.py:2648} INFO - Exporting env vars: AIRFLOW_CTX_DAG_OWNER='airflow' AIRFLOW_CTX_DAG_ID='raw_load_cards' AIRFLOW_CTX_TASK_ID='insert_table' AIRFLOW_CTX_EXECUTION_DATE='2024-07-13T13:10:39.894889+00:00' AIRFLOW_CTX_TRY_NUMBER='1' AIRFLOW_CTX_DAG_RUN_ID='manual__2024-07-13T13:10:39.894889+00:00'
[2024-07-13T18:41:04.611+0530] {taskinstance.py:430} INFO - ::endgroup::
[2024-07-13T18:41:04.641+0530] {logging_mixin.py:188} INFO - card_id`,`customer_id`,`card_number`,`card_type`,`expiration_date`,`security_code`,`ingetion_timestamp
[2024-07-13T18:41:04.644+0530] {logging_mixin.py:188} INFO - ('5b3f6cef-2879-4444-aaf6-9abfcd402f33', '3bceea5b-7d1b-4c04-bb89-4b492566c6cc', 3566158166715041, 'debit', '02/25', 112, Timestamp('2024-07-13 18:41:04.638801'))
[2024-07-13T18:41:04.645+0530] {taskinstance.py:441} INFO - ::group::Post task execution logs
[2024-07-13T18:41:04.646+0530] {taskinstance.py:2905} ERROR - Task failed with exception
Traceback (most recent call last):
  File "/home/kali/Desktop/projects/git/bank_data_processing/myenv/lib/python3.11/site-packages/airflow/models/taskinstance.py", line 465, in _execute_task
    result = _execute_callable(context=context, **execute_callable_kwargs)
             ^^^^^^^^^^^^^^^^^^^^^^^^^^^^^^^^^^^^^^^^^^^^^^^^^^^^^^^^^^^^^
  File "/home/kali/Desktop/projects/git/bank_data_processing/myenv/lib/python3.11/site-packages/airflow/models/taskinstance.py", line 432, in _execute_callable
    return execute_callable(context=context, **execute_callable_kwargs)
           ^^^^^^^^^^^^^^^^^^^^^^^^^^^^^^^^^^^^^^^^^^^^^^^^^^^^^^^^^^^^
  File "/home/kali/Desktop/projects/git/bank_data_processing/myenv/lib/python3.11/site-packages/airflow/models/baseoperator.py", line 401, in wrapper
    return func(self, *args, **kwargs)
           ^^^^^^^^^^^^^^^^^^^^^^^^^^^
  File "/home/kali/Desktop/projects/git/bank_data_processing/myenv/lib/python3.11/site-packages/airflow/operators/python.py", line 235, in execute
    return_value = self.execute_callable()
                   ^^^^^^^^^^^^^^^^^^^^^^^
  File "/home/kali/Desktop/projects/git/bank_data_processing/myenv/lib/python3.11/site-packages/airflow/operators/python.py", line 252, in execute_callable
    return self.python_callable(*self.op_args, **self.op_kwargs)
           ^^^^^^^^^^^^^^^^^^^^^^^^^^^^^^^^^^^^^^^^^^^^^^^^^^^^^
  File "//home/kali/Desktop/projects/git/bank_data_processing/dags/models/raw_models/raw_load_cards.py", line 54, in insert_table
    load_csv_to_mysql(csv_file, table_name)
  File "//home/kali/Desktop/projects/git/bank_data_processing/dags/models/raw_models/raw_load_cards.py", line 48, in load_csv_to_mysql
    cursor.execute(sql, tuple(row))
  File "/home/kali/Desktop/projects/git/bank_data_processing/myenv/lib/python3.11/site-packages/MySQLdb/cursors.py", line 179, in execute
    res = self._query(mogrified_query)
          ^^^^^^^^^^^^^^^^^^^^^^^^^^^^
  File "/home/kali/Desktop/projects/git/bank_data_processing/myenv/lib/python3.11/site-packages/MySQLdb/cursors.py", line 330, in _query
    db.query(q)
  File "/home/kali/Desktop/projects/git/bank_data_processing/myenv/lib/python3.11/site-packages/MySQLdb/connections.py", line 261, in query
    _mysql.connection.query(self, query)
MySQLdb.OperationalError: (1054, "Unknown column 'ingetion_timestamp' in 'field list'")
[2024-07-13T18:41:04.653+0530] {taskinstance.py:1206} INFO - Marking task as FAILED. dag_id=raw_load_cards, task_id=insert_table, run_id=manual__2024-07-13T13:10:39.894889+00:00, execution_date=20240713T131039, start_date=20240713T131104, end_date=20240713T131104
[2024-07-13T18:41:04.669+0530] {standard_task_runner.py:110} ERROR - Failed to execute job 1285 for task insert_table ((1054, "Unknown column 'ingetion_timestamp' in 'field list'"); 38198)
[2024-07-13T18:41:04.703+0530] {local_task_job_runner.py:240} INFO - Task exited with return code 1
[2024-07-13T18:41:04.746+0530] {taskinstance.py:3503} INFO - 0 downstream tasks scheduled from follow-on schedule check
[2024-07-13T18:41:04.747+0530] {local_task_job_runner.py:222} INFO - ::endgroup::
