Traceback (most recent call last):
  File "/home/kali/Desktop/projects/git/bank_data_processing/myenv/lib/python3.11/site-packages/psutil/_pslinux.py", line 1717, in wrapper
    return fun(self, *args, **kwargs)
           ^^^^^^^^^^^^^^^^^^^^^^^^^^
  File "/home/kali/Desktop/projects/git/bank_data_processing/myenv/lib/python3.11/site-packages/psutil/_common.py", line 508, in wrapper
    raise raise_from(err, None)
          ^^^^^^^^^^^^^^^^^^^^^
  File "<string>", line 3, in raise_from
  File "/home/kali/Desktop/projects/git/bank_data_processing/myenv/lib/python3.11/site-packages/psutil/_common.py", line 506, in wrapper
    return fun(self)
           ^^^^^^^^^
  File "/home/kali/Desktop/projects/git/bank_data_processing/myenv/lib/python3.11/site-packages/psutil/_pslinux.py", line 1780, in _parse_stat_file
    data = bcat("%s/%s/stat" % (self._procfs_path, self.pid))
           ^^^^^^^^^^^^^^^^^^^^^^^^^^^^^^^^^^^^^^^^^^^^^^^^^^
  File "/home/kali/Desktop/projects/git/bank_data_processing/myenv/lib/python3.11/site-packages/psutil/_common.py", line 851, in bcat
    return cat(fname, fallback=fallback, _open=open_binary)
           ^^^^^^^^^^^^^^^^^^^^^^^^^^^^^^^^^^^^^^^^^^^^^^^^
  File "/home/kali/Desktop/projects/git/bank_data_processing/myenv/lib/python3.11/site-packages/psutil/_common.py", line 839, in cat
    with _open(fname) as f:
         ^^^^^^^^^^^^
  File "/home/kali/Desktop/projects/git/bank_data_processing/myenv/lib/python3.11/site-packages/psutil/_common.py", line 799, in open_binary
    return open(fname, "rb", buffering=FILE_READ_BUFFER_SIZE)
           ^^^^^^^^^^^^^^^^^^^^^^^^^^^^^^^^^^^^^^^^^^^^^^^^^^
FileNotFoundError: [Errno 2] No such file or directory: '/proc/3558/stat'

During handling of the above exception, another exception occurred:

Traceback (most recent call last):
  File "/home/kali/Desktop/projects/git/bank_data_processing/myenv/lib/python3.11/site-packages/psutil/__init__.py", line 355, in _init
    self.create_time()
  File "/home/kali/Desktop/projects/git/bank_data_processing/myenv/lib/python3.11/site-packages/psutil/__init__.py", line 757, in create_time
    self._create_time = self._proc.create_time()
                        ^^^^^^^^^^^^^^^^^^^^^^^^
  File "/home/kali/Desktop/projects/git/bank_data_processing/myenv/lib/python3.11/site-packages/psutil/_pslinux.py", line 1717, in wrapper
    return fun(self, *args, **kwargs)
           ^^^^^^^^^^^^^^^^^^^^^^^^^^
  File "/home/kali/Desktop/projects/git/bank_data_processing/myenv/lib/python3.11/site-packages/psutil/_pslinux.py", line 1948, in create_time
    ctime = float(self._parse_stat_file()['create_time'])
                  ^^^^^^^^^^^^^^^^^^^^^^^
  File "/home/kali/Desktop/projects/git/bank_data_processing/myenv/lib/python3.11/site-packages/psutil/_pslinux.py", line 1726, in wrapper
    raise NoSuchProcess(self.pid, self._name)
psutil.NoSuchProcess: process no longer exists (pid=3558)

During handling of the above exception, another exception occurred:

Traceback (most recent call last):
  File "/home/kali/Desktop/projects/git/bank_data_processing/myenv/bin/airflow", line 8, in <module>
    sys.exit(main())
             ^^^^^^
  File "/home/kali/Desktop/projects/git/bank_data_processing/myenv/lib/python3.11/site-packages/airflow/__main__.py", line 58, in main
    args.func(args)
  File "/home/kali/Desktop/projects/git/bank_data_processing/myenv/lib/python3.11/site-packages/airflow/cli/cli_config.py", line 49, in command
    return func(*args, **kwargs)
           ^^^^^^^^^^^^^^^^^^^^^
  File "/home/kali/Desktop/projects/git/bank_data_processing/myenv/lib/python3.11/site-packages/airflow/utils/cli.py", line 114, in wrapper
    return f(*args, **kwargs)
           ^^^^^^^^^^^^^^^^^^
  File "/home/kali/Desktop/projects/git/bank_data_processing/myenv/lib/python3.11/site-packages/airflow/utils/providers_configuration_loader.py", line 55, in wrapped_function
    return func(*args, **kwargs)
           ^^^^^^^^^^^^^^^^^^^^^
  File "/home/kali/Desktop/projects/git/bank_data_processing/myenv/lib/python3.11/site-packages/airflow/cli/commands/webserver_command.py", line 485, in webserver
    run_command_with_daemon_option(
  File "/home/kali/Desktop/projects/git/bank_data_processing/myenv/lib/python3.11/site-packages/airflow/cli/commands/daemon_utils.py", line 80, in run_command_with_daemon_option
    callback()
  File "/home/kali/Desktop/projects/git/bank_data_processing/myenv/lib/python3.11/site-packages/airflow/cli/commands/webserver_command.py", line 488, in <lambda>
    callback=lambda: start_and_monitor_gunicorn(args),
                     ^^^^^^^^^^^^^^^^^^^^^^^^^^^^^^^^
  File "/home/kali/Desktop/projects/git/bank_data_processing/myenv/lib/python3.11/site-packages/airflow/cli/commands/webserver_command.py", line 471, in start_and_monitor_gunicorn
    gunicorn_master_proc = psutil.Process(gunicorn_master_proc_pid)
                           ^^^^^^^^^^^^^^^^^^^^^^^^^^^^^^^^^^^^^^^^
  File "/home/kali/Desktop/projects/git/bank_data_processing/myenv/lib/python3.11/site-packages/psutil/__init__.py", line 319, in __init__
    self._init(pid)
  File "/home/kali/Desktop/projects/git/bank_data_processing/myenv/lib/python3.11/site-packages/psutil/__init__.py", line 368, in _init
    raise NoSuchProcess(pid, msg=msg)
psutil.NoSuchProcess: process PID not found (pid=3558)
